#VRML_SIM R2023a utf8

EXTERNPROTO "https://raw.githubusercontent.com/cyberbotics/webots/R2023a/projects/objects/backgrounds/protos/TexturedBackground.proto"
EXTERNPROTO "https://raw.githubusercontent.com/cyberbotics/webots/R2023a/projects/objects/backgrounds/protos/TexturedBackgroundLight.proto"
EXTERNPROTO "https://raw.githubusercontent.com/cyberbotics/webots/R2023a/projects/robots/adept/pioneer3/protos/Pioneer3at.proto"
EXTERNPROTO "https://raw.githubusercontent.com/cyberbotics/webots/R2023a/projects/appearances/protos/CorrodedMetal.proto"
EXTERNPROTO "https://raw.githubusercontent.com/cyberbotics/webots/R2023a/projects/appearances/protos/OsbWood.proto"
EXTERNPROTO "https://raw.githubusercontent.com/cyberbotics/webots/R2023a/projects/objects/floors/protos/Floor.proto"
EXTERNPROTO "https://raw.githubusercontent.com/cyberbotics/webots/R2023a/projects/appearances/protos/Parquetry.proto"

WorldInfo {
  info [
    "This example shows an integration of OpenAI Gym with Webots."
  ]
  title "OpenAI Gym Environment"
}
Viewpoint {
  orientation 0 0 -1 1.5707963267948966
  position -0.2899865201046191 4.475905866037503 0.4156473454832867
}
TexturedBackground {
}
TexturedBackgroundLight {
}
Pioneer3at {
  hidden rotation_3 0.5773516026262935 -0.5773476026290115 -0.5773516023043358 2.094405000321726
  hidden rotation_4 0.5773516026138068 -0.577347602616559 -0.5773516023292745 2.094405000284403
  hidden rotation_5 0.57735160254498 -0.5773476025477347 -0.5773516024669251 2.094405000077784
  hidden rotation_6 0.5773516026102156 -0.5773476026129313 -0.5773516023364936 2.0944050002734214
  controller "openai_gym_ga"
  supervisor TRUE
  extensionSlot [
    HingeJoint {
      jointParameters HingeJointParameters {
        axis 0 1 0
        anchor 0 0 0.21
        minStop -1
        maxStop 1
      }
      device [
        PositionSensor {
        }
      ]
      endPoint Solid {
        translation 3.7296554733501353e-16 0 0.5100000000007157
        rotation 0 1 0 0
        children [
          DEF POLE_ENDPOINT Solid {
            translation 0 0 0.26
            children [
              DEF BALL_SHAPE Shape {
                appearance CorrodedMetal {
                }
                geometry Sphere {
                  radius 0.1
                  subdivision 3
                }
              }
            ]
            boundingObject USE BALL_SHAPE
            physics Physics {
              density -1
              mass 0.2
            }
          }
          DEF POLE_SHAPE Shape {
            appearance OsbWood {
            }
            geometry Cylinder {
              height 0.5
              radius 0.011
            }
          }
        ]
        boundingObject USE POLE_SHAPE
        physics Physics {
        }
      }
    }
  ]
}
Floor {
  appearance Parquetry {
    type "light strip"
  }
}
